Workbook

Sheet Orders
A1: S.No. | B1: Alias Name | C1: Retailer Id | D1: Area | E1: Retailer Name | F1: Amount To be Collect | G1: Total Order | H1: Carry Amt to collect | I1: 44348 | J1: 44349 | K1: 44350 | L1: 44351 | M1: 44352 | N1: 44353 | O1: 44354 | P1: 44355 | Q1: 44356 | R1: 44357 | S1: 44358 | T1: 44359 | U1: 44360 | V1: 44361 | W1: 44362 | X1: 44363 | Y1: 44364 | Z1: 44365 | AA1: 44366 | AB1: 44367 | AC1: 44368 | AD1: 44369 | AE1: 44370 | AF1: 44371 | AG1: 44372 | AH1: 44373 | AI1: 44374 | AJ1: 44375 | AK1: 44376 | AL1: 44377
B2: =SUM(F3:F121) -> 279900 | D2: =SUM(G3:G121) -> 10400 | E2: Total: | F2: =G2/1.04+H2 -> 279900 | G2: =SUM(I2:AM2) -> 10400 | H2: =SUM(H3:H121) -> 269900 | I2: =SUM(I3:I121) -> 10400 | J2: =SUM(J3:J121) -> 0 | K2: =SUM(K3:K121) -> 0 | L2: =SUM(L3:L121) -> 0 | M2: =SUM(M3:M121) -> 0 | N2: =SUM(N3:N121) -> 0 | O2: =SUM(O3:O121) -> 0 | ... AL2: =SUM(AL3:AL121) -> 0
A3: 1 | D3: AGNOOR | E3: S K COMMUNICATION(661475194) | F3: =G3/1.04+H3 -> 0 | G3: =SUM(I3:AM3) -> 0 | H3: 0
A4: 2 | D4: AGNOOR | E4: SAJNISH KIRANA(661644709) | F4: =G4/1.04+H4 -> 0 | G4: =SUM(I4:AM4) -> 0 | H4: 0
A5: 3 | B5: Amit | D5: AGNOOR | E5: MAHI TELECOM ELECTRONICS(661644706) | F5: =G5/1.04+H5 -> 0 | G5: =SUM(I5:AM5) -> 0 | H5: 0
A6: 4 | B6: Ganesh | D6: AGNOOR | E6: ARVIND AIRTEL EGRECHARGE CENTR(661591709) | F6: =G6/1.04+H6 -> 0 | G6: =SUM(I6:AM6) -> 0 | H6: 0
A7: 5 | B7: shakti | D7: AGNOOR | E7: pawan and ravi telicom(660604868) | F7: =G7/1.04+H7 -> 17000 | G7: =SUM(I7:AM7) -> 0 | H7: 17000
A8: 6 | B8: Satish | D8: AGNOOR | E8: PRABHAT TELECOM & ELECTRIC(661066820) | F8: =G8/1.04+H8 -> 0 | G8: =SUM(I8:AM8) -> 0 | H8: 0
A9: 7 | D9: AGNOOR | E9: SINGH TELECOM(661066803) | F9: =G9/1.04+H9 -> 0 | G9: =SUM(I9:AM9) -> 0 | H9: 0
A10: 8 | B10: Ankit | D10: AGNOOR | E10: ANKIT TELECOM(660324751) | F10: =G10/1.04+H10 -> 5000 | G10: =SUM(I10:AM10) -> 0 | H10: 5000
A11: 9 | D11: KALER | E11: NAVEEN MOBILE CENTRE(660903120) | F11: =G11/1.04+H11 -> 0 | G11: =SUM(I11:AM11) -> 0 | H11: 0
A12: 10 | D12: KALER | E12: SANTOSH PUSTAK BHANDAR(661063900) | F12: =G12/1.04+H12 -> 2000 | G12: =SUM(I12:AM12) -> 0 | H12: 2000
A13: 11 | D13: KALER | E13: RAJA MOBILE CENTER(661032976) | F13: =G13/1.04+H13 -> 5000 | G13: =SUM(I13:AM13) -> 0 | H13: 5000
A14: 12 | D14: KALER | E14: KALLU JI DOWN LOADING CENTRE(661066808) | F14: =G14/1.04+H14 -> 8500 | G14: =SUM(I14:AM14) -> 2080 | H14: 6500 | I14: 2080
A15: 13 | B15: Praduman | D15: KALER | E15: NAVEEN RECHARGE CENTRE(661474491) | F15: =G15/1.04+H15 -> 2000 | G15: =SUM(I15:AM15) -> 0 | H15: 2000
A16: 14 | D16: KALER | E16: Rohit Mobile Care-(662161247) | F16: =G16/1.04+H16 -> 2000 | G16: =SUM(I16:AM16) -> 0 | H16: 2000
A17: 15 | B17: Vikash Amir Bigha | D17: KALER | E17: BHUMIKA ELECTRONICS(660320662) | F17: =G17/1.04+H17 -> 5000 | G17: =SUM(I17:AM17) -> 0 | H17: 5000
A18: 16 | B18: Amit Amir Bigha | C18: 683909556 | D18: KALER | E18: KRISHNA KIRANA STORE(661613674) | F18: =G18/1.04+H18 -> 2000 | G18: =SUM(I18:AM18) -> 0 | H18: 2000
A19: 17 | D19: KALER | E19: Glaxy Mobile and Digital Studi(660587311) | F19: =G19/1.04+H19 -> 0 | G19: =SUM(I19:AM19) -> 0 | H19: 0
A20: 18 | D20: MAHENDIA | E20: SINGH COMMUNICATION(660315658) | F20: =G20/1.04+H20 -> 0 | G20: =SUM(I20:AM20) -> 0 | H20: 0
A21: 19 | D21: MAHENDIA | E21: ASHU COMMUNICATION(661025161) | F21: =G21/1.04+H21 -> 2000 | G21: =SUM(I21:AM21) -> 0 | H21: 2000
A22: 20 | D22: MAHENDIA | E22: ANIL PAN DUKAN(661705269) | F22: =G22/1.04+H22 -> 1000 | G22: =SUM(I22:AM22) -> 0 | H22: 1000
A23: 21 | D23: MAHENDIA | E23: MAA VINDHWASHNI COMMUNICATION(660301564) | F23: =G23/1.04+H23 -> 6000 | G23: =SUM(I23:AM23) -> 2080 | H23: 4000 | I23: 2080
A24: 22 | D24: MAHENDIA | E24: MUKESH PAN BHANDAR(661613669) | F24: =G24/1.04+H24 -> 0 | G24: =SUM(I24:AM24) -> 0 | H24: 0
A25: 23 | D25: MAHENDIA | E25: Maa Bhindwashni Mobile Center(660587310) | F25: =G25/1.04+H25 -> 2000 | G25: =SUM(I25:AM25) -> 0 | H25: 2000
A26: 24 | D26: MAHENDIA | E26: MS RIYA ENTERPRISES(661562283) | F26: =G26/1.04+H26 -> 4000 | G26: =SUM(I26:AM26) -> 2080 | H26: 2000 | I26: 2080
A27: 25 | D27: MAHENDIA | E27: ANKIT MOBILE CENTRE(661025000) | F27: =G27/1.04+H27 -> 4000 | G27: =SUM(I27:AM27) -> 0 | H27: 4000
A28: 26 | D28: MAHENDIA | E28: Sahaj Vasudha Kendra(660624994) | F28: =G28/1.04+H28 -> 2000 | G28: =SUM(I28:AM28) -> 0 | H28: 2000
A29: 27 | D29: MAHENDIA | E29: rangoli singar general store(660604869) | F29: =G29/1.04+H29 -> 0 | G29: =SUM(I29:AM29) -> 0 | H29: 0
A30: 28 | D30: MAHENDIA | E30: SUBODH PAN(661562286) | F30: =G30/1.04+H30 -> 4000 | G30: =SUM(I30:AM30) -> 0 | H30: 4000
A31: 29 | D31: MAHENDIA | E31: GUPTA PAN DUKAN(661063901) | F31: =G31/1.04+H31 -> 0 | G31: =SUM(I31:AM31) -> 0 | H31: 0
A32: 30 | D32: MAHENDIA | E32: SUMAN PHONE GHAR(660315655) | F32: =G32/1.04+H32 -> 10000 | G32: =SUM(I32:AM32) -> 0 | H32: 10000
A33: 31 | D33: MAHENDIA | E33: BAJRANG MOBILE ELECTRIC & ELEC(661591707) | F33: =G33/1.04+H33 -> 4000 | G33: =SUM(I33:AM33) -> 0 | H33: 4000
A34: 32 | D34: WALIDAD | E34: ALL THE BEST COMMUNICATION(661096390) | F34: =G34/1.04+H34 -> 4000 | G34: =SUM(I34:AM34) -> 2080 | H34: 2000 | I34: 2080
A35: 33 | D35: WALIDAD | E35: NOKIA REPAIRING CENTER(660301577) | F35: =G35/1.04+H35 -> 3000 | G35: =SUM(I35:AM35) -> 0 | H35: 3000
A36: 34 | D36: WALIDAD | E36: PRINCE COMMUNICATION(660831270) | F36: =G36/1.04+H36 -> 0 | G36: =SUM(I36:AM36) -> 0 | H36: 0
A37: 35 | D37: WALIDAD | E37: Vicky Communication(660614434) | F37: =G37/1.04+H37 -> 0 | G37: =SUM(I37:AM37) -> 0 | H37: 0
A38: 36 | D38: WALIDAD | E38: Kaler Electronics(660628532) | F38: =G38/1.04+H38 -> 0 | G38: =SUM(I38:AM38) -> 0 | H38: 0
A39: 37 | D39: WALIDAD | E39: MS OM COMPUTER(661542289) | F39: =G39/1.04+H39 -> 0 | G39: =SUM(I39:AM39) -> 0 | H39: 0
A40: 38 | C40: 684087396 | D40: WALIDAD | E40: SANTU KIRANA STORE(661752211) | F40: =G40/1.04+H40 -> 2000 | G40: =SUM(I40:AM40) -> 0 | H40: 2000
...

Sheet Collection
A1: S.No. | B1: Alias Name | C1: S.No. | D1: Alias Name | E1: Contact | F1: Area | G1: Retailer Name | H1: Total | I1: 44348 | J1: 44349 | K1: 44350 | L1: 44351 | M1: 44352 | N1: 44353 | O1: 44354 | P1: 44355 | Q1: 44356 | R1: 44357 | S1: 44358 | T1: 44359 | U1: 44360 | V1: 44361 | W1: 44362 | X1: 44363 | Y1: 44364 | Z1: 44365 | AA1: 44366 | AB1: 44367 | AC1: 44368 | AD1: 44369 | AE1: 44370 | AF1: 44371 | AG1: 44372 | AH1: 44373 | AI1: 44374 | AJ1: 44375 | AK1: 44376 | AL1: 44377
F2: =SUM(H3:H121) -> 0 | G2: Total: | H2: =SUM(I2:AM2) -> 0 | I2: =SUM(I3:I121) -> 0 | J2: =SUM(J3:J121) -> 0 | K2: =SUM(K3:K121) -> 0 | L2: =SUM(L3:L121) -> 0 | M2: =SUM(M3:M121) -> 0 | N2: =SUM(N3:N121) -> 0 | O2: =SUM(O3:O121) -> 0 | P2: =SUM(P3:P121) -> 0 | ... AL2: =SUM(AL3:AL121) -> 0
A3: 1 | B3: Sanjeev Kr. Rahi | C3: 1 | D3: Sanjeev Kr. Rahi | E3: 9334066332 | F3: AGNOOR | G3: S K COMMUNICATION(661475194) | H3: =SUM(I3:AM3) -> 0
A4: 2 | B4: Abhimanyu | C4: 2 | D4: Abhimanyu | E4: 9123417146/7979995728 | F4: AGNOOR | G4: SAJNISH KIRANA(661644709) | H4: =SUM(I4:AM4) -> 0
A5: 3 | C5: 3 | E5: 8340365412 | F5: AGNOOR | G5: MAHI TELECOM ELECTRONICS(661644706) | H5: =SUM(I5:AM5) -> 0
A6: 4 | B6: Ganesh Lal Khatri | C6: 4 | D6: Ganesh Lal Khatri | E6: 9102317719 | F6: AGNOOR | G6: ARVIND AIRTEL EGRECHARGE CENTR(661591709) | H6: =SUM(I6:AM6) -> 0
A7: 5 | B7: Shakti | C7: 5 | D7: Shakti/Ashok | E7: 8210924561 | F7: AGNOOR | G7: pawan and ravi telicom(660604868) | H7: =SUM(I7:AM7) -> 0
A8: 6 | C8: 6 | D8: Shashi Satish | E8: 9110978139 | F8: AGNOOR | G8: PRABHAT TELECOM & ELECTRIC(661066820) | H8: =SUM(I8:AM8) -> 0
A9: 7 | C9: 7 | D9: NAVIN KUM | E9: 8340201321 | F9: AGNOOR | G9: SINGH TELECOM(661066803) | H9: =SUM(I9:AM9) -> 0
A10: 8 | C10: 8 | D10: SUCHENDRA | E10: 7004365158 | F10: AGNOOR | G10: ANKIT TELECOM(660324751) | H10: =SUM(I10:AM10) -> 0
A11: 9 | B11: Naveen | C11: 9 | D11: Naveen | E11: 9973022718 | F11: KALER | G11: NAVEEN MOBILE CENTRE(660903120) | H11: =SUM(I11:AM11) -> 0
A12: 10 | C12: 10 | E12: 7004923653 | F12: KALER | G12: SANTOSH PUSTAK BHANDAR(661063900) | H12: =SUM(I12:AM12) -> 0
A13: 11 | C13: 11 | D13: Reyazul | E13: 8340182577 | F13: KALER | G13: RAJA MOBILE CENTER(661032976) | H13: =SUM(I13:AM13) -> 0
A14: 12 | B14: MD Gulam | C14: 12 | D14: MD Gulam,Rina kri,SUAIB AK | E14: 7004740439 | F14: KALER | G14: KALLU JI DOWN LOADING CENTRE(661066808) | H14: =SUM(I14:AM14) -> 0
A15: 13 | B15: Praduman | C15: 13 | D15: Praduman | F15: KALER | G15: NAVEEN RECHARGE CENTRE(661474491) | H15: =SUM(I15:AM15) -> 0
A16: 14 | B16: Sushil Kr. | C16: 14 | D16: Sushil Kr. | E16: 7321004323 | F16: KALER | G16: Rohit Mobile Care-(662161247) | H16: =SUM(I16:AM16) -> 0
A17: 15 | C17: 15 | D17: Vikas Amir Bigha | E17: 7903378748 | F17: KALER | G17: BHUMIKA ELECTRONICS(660320662) | H17: =SUM(I17:AM17) -> 0
A18: 16 | C18: 16 | D18: Amit Amir Bigha | F18: KALER | G18: KRISHNA KIRANA STORE(661613674) | H18: =SUM(I18:AM18) -> 0
A19: 17 | B19: Ranveer/Rina | C19: 17 | D19: Ranveer/Rina | E19: 9608475282 | F19: KALER | G19: Glaxy Mobile and Digital Studi(660587311) | H19: =SUM(I19:AM19) -> 0
A20: 18 | B20: Sailesh | C20: 18 | D20: SHAILESH | E20: 9661555592 | F20: MAHENDIA | G20: SINGH COMMUNICATION(660315658) | H20: =SUM(I20:AM20) -> 0
A21: 19 | B21: Ajay 9939757903 | C21: 19 | D21: Ajay 9939757903 | E21: 8340523512 | F21: MAHENDIA | G21: ASHU COMMUNICATION(661025161) | H21: =SUM(I21:AM21) -> 0
A22: 20 | C22: 20 | D22: Sudhir Bandhan bank | E22: 8825310472 | F22: MAHENDIA | G22: ANIL PAN DUKAN(661705269) | H22: =SUM(I22:AM22) -> 0
A23: 21 | B23: Aarti 9523733118 | C23: 21 | D23: Aarti 9523733118 | E23: 7004478123 | F23: MAHENDIA | G23: MAA VINDHWASHNI COMMUNICATION(660301564) | H23: =SUM(I23:AM23) -> 0
A24: 22 | C24: 22 | E24: 7667895364 | F24: MAHENDIA | G24: MUKESH PAN BHANDAR(661613669) | H24: =SUM(I24:AM24) -> 0
A25: 23 | B25: Rajnish Kr 9708003669 | C25: 23 | D25: Rajnish Kr 9708003669 | E25: 7006041121 | F25: MAHENDIA | G25: Maa Bhindwashni Mobile Center(660587310) | H25: =SUM(I25:AM25) -> 0
A26: 24 | B26: Shantnu Kr. | C26: 24 | D26: Shantnu Kr. | E26: 8709658240 | F26: MAHENDIA | G26: MS RIYA ENTERPRISES(661562283) | H26: =SUM(I26:AM26) -> 0
A27: 25 | C27: 25 | E27: 8709612020 | F27: MAHENDIA | G27: ANKIT MOBILE CENTRE(661025000) | H27: =SUM(I27:AM27) -> 0
A28: 26 | C28: 26 | D28: Munna Kr.(PNB)/Manish | E28: 9973040600 | F28: MAHENDIA | G28: Sahaj Vasudha Kendra(660624994) | H28: =SUM(I28:AM28) -> 0
A29: 27 | C29: 27 | D29: YASHWANT | E29: 9973345687 | F29: MAHENDIA | G29: rangoli singar general store(660604869) | H29: =SUM(I29:AM29) -> 0
A30: 28 | C30: 28 | E30: 9631391206 | F30: MAHENDIA | G30: SUBODH PAN(661562286) | H30: =SUM(I30:AM30) -> 0
A31: 29 | B31: Nitish Kr. | C31: 29 | D31: Nitish Kr./SURESH SA/ | F31: MAHENDIA | G31: GUPTA PAN DUKAN(661063901) | H31: =SUM(I31:AM31) -> 0
A32: 30 | B32: Basant Kr. | C32: 30 | D32: Basant Kr./SHREE | F32: MAHENDIA | G32: SUMAN PHONE GHAR(660315655) | H32: =SUM(I32:AM32) -> 0
A33: 31 | C33: 31 | F33: MAHENDIA | G33: BAJRANG MOBILE ELECTRIC & ELEC(661591707) | H33: =SUM(I33:AM33) -> 0
A34: 32 | B34: Binay Lal | C34: 32 | D34: Binay Lal | F34: WALIDAD | G34: ALL THE BEST COMMUNICATION(661096390) | H34: =SUM(I34:AM34) -> 0
A35: 33 | C35: 33 | D35: ABINESH | F35: WALIDAD | G35: NOKIA REPAIRING CENTER(660301577) | H35: =SUM(I35:AM35) -> 0
A36: 34 | C36: 34 | D36: Arman Ala | E36: 7654800030 | F36: WALIDAD | G36: PRINCE COMMUNICATION(660831270) | H36: =SUM(I36:AM36) -> 0
A37: 35 | C37: 35 | D37: VIKESH/ VK | F37: WALIDAD | G37: Vicky Communication(660614434) | H37: =SUM(I37:AM37) -> 0
A38: 36 | C38: 36 | F38: WALIDAD | G38: Kaler Electronics(660628532) | H38: =SUM(I38:AM38) -> 0
A39: 37 | B39: Sonu/Rupa 9708329918 | C39: 37 | D39: Sonu/Rupa 9708329918 | F39: WALIDAD | G39: MS OM COMPUTER(661542289) | H39: =SUM(I39:AM39) -> 0
A40: 38 | B40: PK | C40: 38 | D40: PK | E40: 8709954402/6207783075 | F40: WALIDAD | G40: SANTU KIRANA STORE(661752211) | H40: =SUM(I40:AM40) -> 0
...

Sheet AmtToCollect
A1: Area | B1: Contact | C1: Retailer Name | D1: Dues Amount
C2: Total: | D2: =Orders!F2-Collection!H2 -> 279900 | E2: =SUM(D3:D96) -> 279900
A3: AGNOOR | B3: 9334066332 | C3: S K COMMUNICATION(661475194) | D3: =Orders!F3-Collection!H3 -> 0
A4: AGNOOR | B4: 9123417146 | C4: SAJNISH KIRANA(661644709) | D4: =Orders!F4-Collection!H4 -> 0
A5: AGNOOR | B5: 8340365412 | C5: MAHI TELECOM ELECTRONICS(661644706) | D5: =Orders!F5-Collection!H5 -> 0
A6: AGNOOR | B6: 9102317719 | C6: ARVIND AIRTEL EGRECHARGE CENTR(661591709) | D6: =Orders!F6-Collection!H6 -> 0
A7: AGNOOR | B7: 8210924561 | C7: pawan and ravi telicom(660604868) | D7: =Orders!F7-Collection!H7 -> 17000
A8: AGNOOR | B8: 9110978139 | C8: PRABHAT TELECOM & ELECTRIC(661066820) | D8: =Orders!F8-Collection!H8 -> 0
A9: AGNOOR | B9: 8340201321 | C9: SINGH TELECOM(661066803) | D9: =Orders!F9-Collection!H9 -> 0
A10: AGNOOR | B10: 7004365158 | C10: ANKIT TELECOM(660324751) | D10: =Orders!F10-Collection!H10 -> 5000
A11: KALER | B11: 9973022718 | C11: NAVEEN MOBILE CENTRE(660903120) | D11: =Orders!F11-Collection!H11 -> 0
A12: KALER | B12: 7004923653 | C12: SANTOSH PUSTAK BHANDAR(661063900) | D12: =Orders!F12-Collection!H12 -> 2000
A13: KALER | B13: 8340182577 | C13: RAJA MOBILE CENTER(661032976) | D13: =Orders!F13-Collection!H13 -> 5000
A14: KALER | B14: 7004740439 | C14: KALLU JI DOWN LOADING CENTRE(661066808) | D14: =Orders!F14-Collection!H14 -> 8500
... A79: BELSAR | B79: 8789354609 | C79: ANAND SRINGAR STORE(660831268) | D79: =Orders!F79-Collection!H79 -> 1000
C80: ROHIT SHOE STORE(661670729) | D80: =Orders!F80-Collection!H80 -> 67000
A81: Dhewai | B81: 8789783884 | C81: maa phone ghar(662077151) | D81: =Orders!F81-Collection!H81 -> 2000
C82: Payal Communication(660614430) | D82: =Orders!F82-Collection!H82 -> 0
A83: KAMTA | B83: 7079312729 | C83: GRAMOTHAN SEVA KENDRA(661705272) | D83: =Orders!F83-Collection!H83 -> 2000
C84: Rounk Mobile and Electronics(660584652) | D84: =Orders!F84-Collection!H84 -> 0
A85: Arwal | B85: 7979068575 | C85: RAJ PHONE HIRDYACHAK(661712682) | D85: =Orders!F85-Collection!H85 -> 5000
A86: Arwal | B86: 9934079439 | C86: Raj communication(660623659) | D86: =Orders!F86-Collection!H86 -> 5000
A87: Arwal | B87: 7903552643 | C87: SANGAM ENTERPRISES(661591706) | D87: =Orders!F87-Collection!H87 -> 0
A88: Rupsagar | B88: 9911430509 | C88: sugam phone bathe(661711006) | D88: =Orders!F88-Collection!H88 -> 0
C89: JANTA SEVA KENDRA(661752229) | D89: =Orders!F89-Collection!H89 -> 0
A90: KALER | B90: 9905739212 | C90: MUSKAN COMMUNICATION(662077126) | D90: =Orders!F90-Collection!H90 -> 1000
C91: SURAJ KIRANA STORE(661735618) | D91: =Orders!F91-Collection!H91 -> 0
B92: 9015378357 | C92: SANTOSH MOBILE CENTER(660321089) | D92: =Orders!F92-Collection!H92 -> 4000
C93: JANTA MOBILE CENTRE(660322613) | D93: =Orders!F93-Collection!H93 -> 0
B94: 7254967519 | C94: PRADEEP GENERAL STORE(661809210) | D94: =Orders!F94-Collection!H94 -> 3000
C95: 6201704055(662077143) | D95: =Orders!F95-Collection!H95 -> 0
C96: Manish mobile center(662157439) | D96: =Orders!F96-Collection!H96 -> 0
